Workbook
Name L_Uses: Lookups!$A$5:$A$12
Name L_Centres: Lookups!$B$5:$B$29
Name L_YesNo: Lookups!$C$5:$C$6
Name L_Owner: Lookups!$D$5:$D$6
Name L_AreaUnit: Lookups!$E$5:$E$6
Name L_Occupier: Lookups!$F$5:$F$7
Name L_Group: Lookups!$G$5:$G$7
Name L_Scale: Lookups!$H$5:$H$11
Name L_Grades: Lookups!$I$5:$I$10
Name L_CostGrade: Lookups!$J$5:$J$10
Name L_GroupValue: Lookups!$K$5:$K$7
Name L_Tier: Lookups!$L$5:$L$29

Sheet Front
A1: Town Centre Activation Value Model
A3: Version 0.1, 23 October 2026 (pre-Budget; revise after the 28 October 2026 Budget)
A4: What It Does
A5: Estimates the value of bringing a vacant town centre unit in Gateshead into meanwhile use, against the public money it needs. It follows the MHCLG Appraisal Guide (4th edition, February 2026) and the Green Book (2026): welfare-based benefit-cost ratios for Gateshead and for the UK, each with its value for money category, with local GVA, jobs and visitor spend reported as Gateshead indicators outside the ratios.
A6: How to Use It
A7: 1. Enter up to five proposals on the Inputs sheet (yellow cells). One property and one use per column.
A8: 2. Pick the proposal to show in Settings. Results is the one-page summary, Sensitivity holds the switching values and Compare sets all five side by side.
A9: 3. Key in local reference data once on the Static Data sheet: STEAM spend per visit and the council's vacancy survey by centre.
A10: 4. Assumptions are protected. To use a better local figure, enter it in the Local override column with a reason; Results flags any override.
A11: Reading the Results
A12: Low takes the pessimistic end of every ranged assumption, high the optimistic end. Optimism bias follows the Treasury guidance: benefits are cut by up to 40% and costs raised by up to 51% according to the strength of the evidence. Evidence over five years old is graded 6, the weakest, as Treasury Table 7.B requires.
A13: The chance of a commercial let anyway is netted off the benefits. With a break clause the meanwhile use ends if a tenant appears; without one it blocks the let, and the model assumes the blocked tenant would have brought similar jobs and visitors, and counts the rates it would have paid as lost public income. Costs are not reduced.
... A16: Indicative appraisal, not a business case. Built on the register approved on 23 October 2026. To be revised after the 28 October 2026 Budget, which is expected to cut the Green Book discount rate to 3.0% and may bring a new GDP deflator file.

Sheet Inputs
A1: Inputs
A2: Yellow cells are inputs. Up to five proposals, one property and one use each. Blank optional cells use the evidence default.
B4: Input | C4: Proposal 1 | D4: Proposal 2 | E4: Proposal 3 | F4: Proposal 4 | G4: Proposal 5 | H4: Guidance
B5: Proposal
B6: Proposal name | H6: The worked example is hypothetical and describes no real unit
B7: Centre | H7: Local Plan Policy CS7. Metrocentre is outside the hierarchy
B8: Centre tier (filled in automatically) | C8: =IFERROR(INDEX(L_Tier,MATCH(C7,L_Centres,0)),"") | D8: =IFERROR(INDEX(L_Tier,MATCH(D7,L_Centres,0)),"") | E8: =IFERROR(INDEX(L_Tier,MATCH(E7,L_Centres,0)),"") | F8: =IFERROR(INDEX(L_Tier,MATCH(F7,L_Centres,0)),"") | G8: =IFERROR(INDEX(L_Tier,MATCH(G7,L_Centres,0)),"") | H8: Label and place scorecard only (Phase 1b decision 4)
B9: Use | H9: Health and wellbeing means activity-based uses; enter clinical services as a community hub with your own staffing
B10: The property
B11: Floor area (gross internal)
B12: Floor area unit | H12: Blank = sq ft
B13: Rateable value (£) | H13: From the free VOA 'Find a business rates valuation' service. Required: results stay blank without it
B14: Listed building? | H14: Listed empty buildings pay no empty rates
B15: Owner
B16: Book or market value if council-owned (£) | H16: Used for the 2% holding cost only if no security cost is entered
B17: Cost of keeping the unit empty, for security, inspection and maintenance (£ a year) | H17: The council's own figure; no published benchmark exists
B18: Chance the unit is let commercially anyway during the period (optional) | H18: Blank = council vacancy survey for the centre (Static Data), else row B1
B19: Can the landlord end the meanwhile lease for a commercial let? | H19: Standard meanwhile leases allow this. Blank = Yes
B20: The occupation
B21: Occupation period (months, up to 60) | H21: Required
B22: Rent paid by the occupier or its users (£ a year) | H22: The low value of the space (row V2)
B23: Rent paid by the council to a private landlord (£ a year) | H23: A transfer (row V4). Ignored where the council owns the unit
B24: Occupier type for business rates
B25: Eligible for the retail, hospitality and leisure multiplier?
B26: Discretionary relief on the remaining bill | H26: 100% = no rates paid
B27: Public costs
B28: Fit-out and works, capital, at the start (£) | H28: Optimism bias +51% at proposal stage (row C7)
B29: Share of optimism bias risk factors mitigated so far | H29: 0% at proposal stage; steps the fit-out uplift from 51% towards 4%
B30: Operator or management contract (£ a year) | H30: Optimism bias +41% (row C8)
B31: Utilities, insurance and other running costs (£ a year)
B32: Monitoring and evaluation (£ a year) | H32: Green Book 10.8
B33: Evidence behind the running and monitoring costs | H33: Treasury Table 7.A; sets their optimism bias. Blank = 4
B34: Council share of capital cost | H34: The rest from Pride in Place, UKSPF, NEMSA or other funders
B35: Council share of revenue costs
B36: Activity
B37: Staffing, FTE (optional) | H37: Blank = estimate from floor area
B38: or full-time staff (headcount)
B39: and part-time staff (headcount) | H39: 2 part-time = 1 FTE
B40: Share of the space in use against a fully used unit (optional) | H40: Blank = row J9
B41: Regular volunteers who would not otherwise volunteer (average number)
...

Sheet Results
A1: Results
A2: =IF(INDEX(Calculations!$D$6:$R$6,1,(Settings!$B$5-1)*3+2)=1,"Proposal "&Settings!$B$5&IF(INDEX(Inputs!$C$6:$G$6,1,Settings!$B$5)="","",", "&INDEX(Inputs!$C$6:$G$6,1,Settings!$B$5))&" ("&INDEX(Inputs!$C$9:$G$9,1,Settings!$B$5)&IF(INDEX(Inputs!$C$7:$G$7,1,Settings!$B$5)="","",", "&INDEX(Inputs!$C$7:$G$7,1,Settings!$B$5))&", "&TEXT(INDEX(Inputs!$C$21:$G$21,1,Settings!$B$5),"0")&" months)","Proposal "&Settings!$B$5&" has no results yet. Enter at least the use, the occupation period and the rateable value on the Inputs sheet")
A3: Version 0.1, 23 October 2026 (pre-Budget; revise after the 28 October 2026 Budget). Indicative appraisal following the MHCLG Appraisal Guide (2026), not a business case.
A5: Value for Money | B5: Gateshead | C5: UK
A6: Category (central) | B6: =IFERROR(INDEX(Calculations!$D$111:$R$111,1,(Settings!$B$5-1)*3+2),"") | C6: =IFERROR(INDEX(Calculations!$D$116:$R$116,1,(Settings!$B$5-1)*3+2),"")
A7: Category range (low to high) | B7: =INDEX(Calculations!$D$111:$R$111,1,(Settings!$B$5-1)*3+1)&" to "&INDEX(Calculations!$D$111:$R$111,1,(Settings!$B$5-1)*3+3) | C7: =INDEX(Calculations!$D$116:$R$116,1,(Settings!$B$5-1)*3+1)&" to "&INDEX(Calculations!$D$116:$R$116,1,(Settings!$B$5-1)*3+3)
A8: Benefit-cost ratio, central | B8: =IFERROR(INDEX(Calculations!$D$107:$R$107,1,(Settings!$B$5-1)*3+2),"") | C8: =IFERROR(INDEX(Calculations!$D$112:$R$112,1,(Settings!$B$5-1)*3+2),"")
A9: Benefit-cost ratio, low | B9: =IFERROR(INDEX(Calculations!$D$107:$R$107,1,(Settings!$B$5-1)*3+1),"") | C9: =IFERROR(INDEX(Calculations!$D$112:$R$112,1,(Settings!$B$5-1)*3+1),"")
A10: Benefit-cost ratio, high | B10: =IFERROR(INDEX(Calculations!$D$107:$R$107,1,(Settings!$B$5-1)*3+3),"") | C10: =IFERROR(INDEX(Calculations!$D$112:$R$112,1,(Settings!$B$5-1)*3+3),"")
A11: Present value of benefits | B11: =IFERROR(INDEX(Calculations!$D$102:$R$102,1,(Settings!$B$5-1)*3+2),"") | C11: =IFERROR(INDEX(Calculations!$D$103:$R$103,1,(Settings!$B$5-1)*3+2),"") | D11: =IFERROR("Rest of UK: "&TEXT(INDEX(Calculations!$D$104:$R$104,1,(Settings!$B$5-1)*3+2),"£#,##0"),"")
A12: Benefit-cost ratio without the offsetting transfers | B12: =IFERROR(INDEX(Calculations!$D$108:$R$108,1,(Settings!$B$5-1)*3+2),"") | C12: =IFERROR(INDEX(Calculations!$D$113:$R$113,1,(Settings!$B$5-1)*3+2),"")
A13: Net public cost | B13: =IFERROR(INDEX(Calculations!$D$91:$R$91,1,(Settings!$B$5-1)*3+2),"") | C13: =IFERROR(INDEX(Calculations!$D$91:$R$91,1,(Settings!$B$5-1)*3+2),"")
A14: Net present social value | B14: =IFERROR(INDEX(Calculations!$D$110:$R$110,1,(Settings!$B$5-1)*3+2),"") | C14: =IFERROR(INDEX(Calculations!$D$115:$R$115,1,(Settings!$B$5-1)*3+2),"")
A15: Robustness of the analysis | B15: =IFERROR(INDEX(Calculations!$D$118:$R$118,1,(Settings!$B$5-1)*3+2),"") | C15: =IFERROR(INDEX(Calculations!$D$118:$R$118,1,(Settings!$B$5-1)*3+2),"")
A17: Value for Money Statement
A18: =IF(INDEX(Calculations!$D$6:$R$6,1,(Settings!$B$5-1)*3+2)<>1,"","On central assumptions the proposal returns £"&TEXT(INDEX(Calculations!$D$107:$R$107,1,(Settings!$B$5-1)*3+2),"0.00")&" of benefits in Gateshead for each £1 of net public cost, including offsetting transfers such as rates relief (£"&TEXT(INDEX(Calculations!$D$108:$R$108,1,(Settings!$B$5-1)*3+2),"0.00")&" without them), which is "&INDEX(Calculations!$D$111:$R$111,1,(Settings!$B$5-1)*3+2)&" value for money, and £"&TEXT(INDEX(Calculations!$D$112:$R$112,1,(Settings!$B$5-1)*3+2),"0.00")&" across the UK ("&INDEX(Calculations!$D$116:$R$116,1,(Settings!$B$5-1)*3+2)&"). "&IF(INDEX(Calculations!$D$111:$R$111,1,(Settings!$B$5-1)*3+1)=INDEX(Calculations!$D$111:$R$111,1,(Settings!$B$5-1)*3+3),"The Gateshead category is "&INDEX(Calculations!$D$111:$R$111,1,(Settings!$B$5-1)*3+1)&" in every scenario.","Across the low and high scenarios the Gateshead category runs from "&INDEX(Calculations!$D$111:$R$111,1,(Settings!$B$5-1)*3+1)&" to "&INDEX(Calculations!$D$111:$R$111,1,(Settings!$B$5-1)*3+3)&".")&" The analysis is "&LOWER(INDEX(Calculations!$D$118:$R$118,1,(Settings!$B$5-1)*3+2))&" in robustness because the weakest evidence behind the benefits is grade "&INDEX(Calculations!$D$117:$R$117,1,(Settings!$B$5-1)*3+2)&" on the Treasury scale. Local output and jobs are reported below as Gateshead indicators and are not in the ratios, as the Green Book requires.")
A23: Benefits and Costs (central, present value) | B23: Gateshead | C23: UK | D23: Grade
A24: Value of the space | B24: =IFERROR(INDEX(Calculations!$D$53:$R$53,1,(Settings!$B$5-1)*3+2)*INDEX(Calculations!$D$95:$R$95,1,(Settings!$B$5-1)*3+2),"") | C24: =IFERROR(INDEX(Calculations!$D$53:$R$53,1,(Settings!$B$5-1)*3+2)*INDEX(Calculations!$D$95:$R$95,1,(Settings!$B$5-1)*3+2),"") | D24: =IFERROR(INDEX(Calculations!$D$52:$R$52,1,(Settings!$B$5-1)*3+2),"") | E24: =IFERROR(IF(INDEX(Calculations!$D$95:$R$95,1,(Settings!$B$5-1)*3+2)=0,"Outside the ratio (range rule): value "&TEXT(INDEX(Calculations!$D$53:$R$53,1,(Settings!$B$5-1)*3+2),"£#,##0"),""),"")
A25: Volunteering | B25: =IFERROR(INDEX(Calculations!$D$56:$R$56,1,(Settings!$B$5-1)*3+2)*INDEX(Calculations!$D$96:$R$96,1,(Settings!$B$5-1)*3+2),"") | C25: =IFERROR(INDEX(Calculations!$D$56:$R$56,1,(Settings!$B$5-1)*3+2)*INDEX(Calculations!$D$96:$R$96,1,(Settings!$B$5-1)*3+2),"") | E25: =IFERROR(IF(INDEX(Calculations!$D$96:$R$96,1,(Settings!$B$5-1)*3+2)=0,"Outside the ratio (range rule): value "&TEXT(INDEX(Calculations!$D$56:$R$56,1,(Settings!$B$5-1)*3+2),"£#,##0"),""),"")
A26: Regular participation | B26: =IFERROR(INDEX(Calculations!$D$59:$R$59,1,(Settings!$B$5-1)*3+2)*INDEX(Calculations!$D$97:$R$97,1,(Settings!$B$5-1)*3+2),"") | C26: =IFERROR(INDEX(Calculations!$D$59:$R$59,1,(Settings!$B$5-1)*3+2)*INDEX(Calculations!$D$97:$R$97,1,(Settings!$B$5-1)*3+2),"") | E26: =IFERROR(IF(INDEX(Calculations!$D$97:$R$97,1,(Settings!$B$5-1)*3+2)=0,"Outside the ratio (range rule): value "&TEXT(INDEX(Calculations!$D$59:$R$59,1,(Settings!$B$5-1)*3+2),"£#,##0"),""),"")
A27: Employment wellbeing | B27: =IFERROR(INDEX(Calculations!$D$63:$R$63,1,(Settings!$B$5-1)*3+2)*INDEX(Calculations!$D$98:$R$98,1,(Settings!$B$5-1)*3+2),"") | C27: =IFERROR(IF(Settings!$B$8="Yes",INDEX(Calculations!$D$63:$R$63,1,(Settings!$B$5-1)*3+2)*INDEX(Calculations!$D$98:$R$98,1,(Settings!$B$5-1)*3+2),0),"") | D27: =IFERROR(INDEX(Calculations!$D$61:$R$61,1,(Settings!$B$5-1)*3+2),"") | E27: =IFERROR(IF(INDEX(Calculations!$D$98:$R$98,1,(Settings!$B$5-1)*3+2)=0,"Outside the ratio (range rule): value "&TEXT(INDEX(Calculations!$D$63:$R$63,1,(Settings!$B$5-1)*3+2),"£#,##0"),""),"")
A28: Avoided empty-unit costs | B28: =IFERROR(INDEX(Calculations!$D$66:$R$66,1,(Settings!$B$5-1)*3+2)*INDEX(Calculations!$D$99:$R$99,1,(Settings!$B$5-1)*3+2),"") | C28: =IFERROR(INDEX(Calculations!$D$66:$R$66,1,(Settings!$B$5-1)*3+2)*INDEX(Calculations!$D$99:$R$99,1,(Settings!$B$5-1)*3+2),"") | D28: =IFERROR(INDEX(Calculations!$D$65:$R$65,1,(Settings!$B$5-1)*3+2),"") | E28: =IFERROR(IF(INDEX(Calculations!$D$99:$R$99,1,(Settings!$B$5-1)*3+2)=0,"Outside the ratio (range rule): value "&TEXT(INDEX(Calculations!$D$66:$R$66,1,(Settings!$B$5-1)*3+2),"£#,##0"),""),"")
A29: Legacy of a permanent let (if switched on) | B29: =IFERROR(INDEX(Calculations!$D$68:$R$68,1,(Settings!$B$5-1)*3+2)*INDEX(Calculations!$D$100:$R$100,1,(Settings!$B$5-1)*3+2)*IF(Settings!$B$9="Yes",1,0),"") | C29: =IFERROR(INDEX(Calculations!$D$68:$R$68,1,(Settings!$B$5-1)*3+2)*INDEX(Calculations!$D$100:$R$100,1,(Settings!$B$5-1)*3+2)*IF(Settings!$B$9="Yes",1,0),"") | E29: =IFERROR(IF(INDEX(Calculations!$D$100:$R$100,1,(Settings!$B$5-1)*3+2)=0,"Outside the ratio (range rule): value "&TEXT(INDEX(Calculations!$D$68:$R$68,1,(Settings!$B$5-1)*3+2),"£#,##0"),""),"")
A30: Transfers (offsetting) | B30: =IFERROR(INDEX(Calculations!$D$80:$R$80,1,(Settings!$B$5-1)*3+2),"") | C30: =IFERROR(INDEX(Calculations!$D$80:$R$80,1,(Settings!$B$5-1)*3+2),"")
A31: Fit-out | B31: =IFERROR(INDEX(Calculations!$D$83:$R$83,1,(Settings!$B$5-1)*3+2),"") | C31: =IFERROR(INDEX(Calculations!$D$83:$R$83,1,(Settings!$B$5-1)*3+2),"")
A32: Operator contract | B32: =IFERROR(INDEX(Calculations!$D$84:$R$84,1,(Settings!$B$5-1)*3+2),"") | C32: =IFERROR(INDEX(Calculations!$D$84:$R$84,1,(Settings!$B$5-1)*3+2),"")
A33: Running costs | B33: =IFERROR(INDEX(Calculations!$D$86:$R$86,1,(Settings!$B$5-1)*3+2),"") | C33: =IFERROR(INDEX(Calculations!$D$86:$R$86,1,(Settings!$B$5-1)*3+2),"")
A34: Monitoring and evaluation | B34: =IFERROR(INDEX(Calculations!$D$87:$R$87,1,(Settings!$B$5-1)*3+2),"") | C34: =IFERROR(INDEX(Calculations!$D$87:$R$87,1,(Settings!$B$5-1)*3+2),"")
A35: Rent to the landlord | B35: =IFERROR(INDEX(Calculations!$D$88:$R$88,1,(Settings!$B$5-1)*3+2),"") | C35: =IFERROR(INDEX(Calculations!$D$88:$R$88,1,(Settings!$B$5-1)*3+2),"")
A36: Rates income forgone | B36: =IFERROR(INDEX(Calculations!$D$89:$R$89,1,(Settings!$B$5-1)*3+2),"") | C36: =IFERROR(INDEX(Calculations!$D$89:$R$89,1,(Settings!$B$5-1)*3+2),"")
A37: Avoided council costs | B37: =IFERROR(INDEX(Calculations!$D$90:$R$90,1,(Settings!$B$5-1)*3+2),"") | C37: =IFERROR(INDEX(Calculations!$D$90:$R$90,1,(Settings!$B$5-1)*3+2),"")
A38: Net public cost | B38: =IFERROR(INDEX(Calculations!$D$91:$R$91,1,(Settings!$B$5-1)*3+2),"") | C38: =IFERROR(INDEX(Calculations!$D$91:$R$91,1,(Settings!$B$5-1)*3+2),"")
A39: Council share of cash and contract costs (excludes rates) | B39: =IFERROR(INDEX(Calculations!$D$93:$R$93,1,(Settings!$B$5-1)*3+2),"")
A40: Cash budget (nominal) | B40: =IFERROR(INDEX(Calculations!$D$92:$R$92,1,(Settings!$B$5-1)*3+2),"") | C40: =IFERROR(INDEX(Calculations!$D$92:$R$92,1,(Settings!$B$5-1)*3+2),"")
A42: Business as Usual (the unit stays empty), central | B42: Value
A43: Chance of a commercial let anyway during the period | B43: =IFERROR(INDEX(Calculations!$D$22:$R$22,1,(Settings!$B$5-1)*3+2),"")
A44: Empty rates paid by a private owner (£ a year) | B44: =IFERROR(INDEX(Calculations!$D$75:$R$75,1,(Settings!$B$5-1)*3+2),"")
A45: Cost of keeping the unit empty (£ a year, before a let anyway) | B45: =IFERROR(IF(INDEX(Calculations!$D$25:$R$25,1,(Settings!$B$5-1)*3+2)>0,INDEX(Calculations!$D$64:$R$64,1,(Settings!$B$5-1)*3+2)/INDEX(Calculations!$D$25:$R$25,1,(Settings!$B$5-1)*3+2),0),"")
A46: Rates bill a commercial tenant would pay (£ a year) | B46: =IFERROR(INDEX(Calculations!$D$71:$R$71,1,(Settings!$B$5-1)*3+2),"")
A48: Gateshead Indicators (outside the ratios) | B48: Low | C48: Central | D48: High
...

Sheet Sensitivity
A1: Sensitivity and Switching Values
A2: For the proposal chosen in Settings. Switching values show how far the evidence would have to move to change the value for money category.
A4: Test | B4: Gateshead | C4: UK | D4: Reading
A5: Fall in benefits that would drop the category one band | B5: =IFERROR(IF(IF((INDEX(Calculations!$D$107:$R$107,1,(Settings!$B$5-1)*3+2))>=4,4,IF((INDEX(Calculations!$D$107:$R$107,1,(Settings!$B$5-1)*3+2))>=2,2,IF((INDEX(Calculations!$D$107:$R$107,1,(Settings!$B$5-1)*3+2))>=1.5,1.5,IF((INDEX(Calculations!$D$107:$R$107,1,(Settings!$B$5-1)*3+2))>=1,1,0))))=0,"Already Poor or below",1-IF((INDEX(Calculations!$D$107:$R$107,1,(Settings!$B$5-1)*3+2))>=4,4,IF((INDEX(Calculations!$D$107:$R$107,1,(Settings!$B$5-1)*3+2))>=2,2,IF((INDEX(Calculations!$D$107:$R$107,1,(Settings!$B$5-1)*3+2))>=1.5,1.5,IF((INDEX(Calculations!$D$107:$R$107,1,(Settings!$B$5-1)*3+2))>=1,1,0))))*(INDEX(Calculations!$D$91:$R$91,1,(Settings!$B$5-1)*3+2))/(INDEX(Calculations!$D$102:$R$102,1,(Settings!$B$5-1)*3+2))),"") | C5: =IFERROR(IF(IF((INDEX(Calculations!$D$112:$R$112,1,(Settings!$B$5-1)*3+2))>=4,4,IF((INDEX(Calculations!$D$112:$R$112,1,(Settings!$B$5-1)*3+2))>=2,2,IF((INDEX(Calculations!$D$112:$R$112,1,(Settings!$B$5-1)*3+2))>=1.5,1.5,IF((INDEX(Calculations!$D$112:$R$112,1,(Settings!$B$5-1)*3+2))>=1,1,0))))=0,"Already Poor or below",1-IF((INDEX(Calculations!$D$112:$R$112,1,(Settings!$B$5-1)*3+2))>=4,4,IF((INDEX(Calculations!$D$112:$R$112,1,(Settings!$B$5-1)*3+2))>=2,2,IF((INDEX(Calculations!$D$112:$R$112,1,(Settings!$B$5-1)*3+2))>=1.5,1.5,IF((INDEX(Calculations!$D$112:$R$112,1,(Settings!$B$5-1)*3+2))>=1,1,0))))*(INDEX(Calculations!$D$91:$R$91,1,(Settings!$B$5-1)*3+2))/(INDEX(Calculations!$D$103:$R$103,1,(Settings!$B$5-1)*3+2))),"") | D5: Switching value (Green Book 6.104)
A6: Extra benefits needed to reach the next category | B6: =IFERROR(IF(IF((INDEX(Calculations!$D$107:$R$107,1,(Settings!$B$5-1)*3+2))<0,0,IF((INDEX(Calculations!$D$107:$R$107,1,(Settings!$B$5-1)*3+2))<1,1,IF((INDEX(Calculations!$D$107:$R$107,1,(Settings!$B$5-1)*3+2))<1.5,1.5,IF((INDEX(Calculations!$D$107:$R$107,1,(Settings!$B$5-1)*3+2))<2,2,IF((INDEX(Calculations!$D$107:$R$107,1,(Settings!$B$5-1)*3+2))<4,4,"")))))="","Already Very High",IF((INDEX(Calculations!$D$107:$R$107,1,(Settings!$B$5-1)*3+2))<0,0,IF((INDEX(Calculations!$D$107:$R$107,1,(Settings!$B$5-1)*3+2))<1,1,IF((INDEX(Calculations!$D$107:$R$107,1,(Settings!$B$5-1)*3+2))<1.5,1.5,IF((INDEX(Calculations!$D$107:$R$107,1,(Settings!$B$5-1)*3+2))<2,2,IF((INDEX(Calculations!$D$107:$R$107,1,(Settings!$B$5-1)*3+2))<4,4,"")))))*(INDEX(Calculations!$D$91:$R$91,1,(Settings!$B$5-1)*3+2))-(INDEX(Calculations!$D$102:$R$102,1,(Settings!$B$5-1)*3+2))),"") | C6: =IFERROR(IF(IF((INDEX(Calculations!$D$112:$R$112,1,(Settings!$B$5-1)*3+2))<0,0,IF((INDEX(Calculations!$D$112:$R$112,1,(Settings!$B$5-1)*3+2))<1,1,IF((INDEX(Calculations!$D$112:$R$112,1,(Settings!$B$5-1)*3+2))<1.5,1.5,IF((INDEX(Calculations!$D$112:$R$112,1,(Settings!$B$5-1)*3+2))<2,2,IF((INDEX(Calculations!$D$112:$R$112,1,(Settings!$B$5-1)*3+2))<4,4,"")))))="","Already Very High",IF((INDEX(Calculations!$D$112:$R$112,1,(Settings!$B$5-1)*3+2))<0,0,IF((INDEX(Calculations!$D$112:$R$112,1,(Settings!$B$5-1)*3+2))<1,1,IF((INDEX(Calculations!$D$112:$R$112,1,(Settings!$B$5-1)*3+2))<1.5,1.5,IF((INDEX(Calculations!$D$112:$R$112,1,(Settings!$B$5-1)*3+2))<2,2,IF((INDEX(Calculations!$D$112:$R$112,1,(Settings!$B$5-1)*3+2))<4,4,"")))))*(INDEX(Calculations!$D$91:$R$91,1,(Settings!$B$5-1)*3+2))-(INDEX(Calculations!$D$103:$R$103,1,(Settings!$B$5-1)*3+2))),"")
A7: Residents feeling more pride in place needed to reach the next category | B7: =IFERROR(IF(IF((INDEX(Calculations!$D$107:$R$107,1,(Settings!$B$5-1)*3+2))<0,0,IF((INDEX(Calculations!$D$107:$R$107,1,(Settings!$B$5-1)*3+2))<1,1,IF((INDEX(Calculations!$D$107:$R$107,1,(Settings!$B$5-1)*3+2))<1.5,1.5,IF((INDEX(Calculations!$D$107:$R$107,1,(Settings!$B$5-1)*3+2))<2,2,IF((INDEX(Calculations!$D$107:$R$107,1,(Settings!$B$5-1)*3+2))<4,4,"")))))="","",(IF((INDEX(Calculations!$D$107:$R$107,1,(Settings!$B$5-1)*3+2))<0,0,IF((INDEX(Calculations!$D$107:$R$107,1,(Settings!$B$5-1)*3+2))<1,1,IF((INDEX(Calculations!$D$107:$R$107,1,(Settings!$B$5-1)*3+2))<1.5,1.5,IF((INDEX(Calculations!$D$107:$R$107,1,(Settings!$B$5-1)*3+2))<2,2,IF((INDEX(Calculations!$D$107:$R$107,1,(Settings!$B$5-1)*3+2))<4,4,"")))))*(INDEX(Calculations!$D$91:$R$91,1,(Settings!$B$5-1)*3+2))-(INDEX(Calculations!$D$102:$R$102,1,(Settings!$B$5-1)*3+2)))/(Assumptions!$O$86*(INDEX(Calculations!$D$15:$R$15,1,(Settings!$B$5-1)*3+2)))),"") | C7: =IFERROR(IF(IF((INDEX(Calculations!$D$112:$R$112,1,(Settings!$B$5-1)*3+2))<0,0,IF((INDEX(Calculations!$D$112:$R$112,1,(Settings!$B$5-1)*3+2))<1,1,IF((INDEX(Calculations!$D$112:$R$112,1,(Settings!$B$5-1)*3+2))<1.5,1.5,IF((INDEX(Calculations!$D$112:$R$112,1,(Settings!$B$5-1)*3+2))<2,2,IF((INDEX(Calculations!$D$112:$R$112,1,(Settings!$B$5-1)*3+2))<4,4,"")))))="","",(IF((INDEX(Calculations!$D$112:$R$112,1,(Settings!$B$5-1)*3+2))<0,0,IF((INDEX(Calculations!$D$112:$R$112,1,(Settings!$B$5-1)*3+2))<1,1,IF((INDEX(Calculations!$D$112:$R$112,1,(Settings!$B$5-1)*3+2))<1.5,1.5,IF((INDEX(Calculations!$D$112:$R$112,1,(Settings!$B$5-1)*3+2))<2,2,IF((INDEX(Calculations!$D$112:$R$112,1,(Settings!$B$5-1)*3+2))<4,4,"")))))*(INDEX(Calculations!$D$91:$R$91,1,(Settings!$B$5-1)*3+2))-(INDEX(Calculations!$D$103:$R$103,1,(Settings!$B$5-1)*3+2)))/(Assumptions!$O$86*(INDEX(Calculations!$D$15:$R$15,1,(Settings!$B$5-1)*3+2)))),"") | D7: At £4,620 a person a year (HACT value used by MHCLG); switching test only, never in a ratio (decision 6)
A8: People moved from moderate to mild loneliness needed to reach the next category | B8: =IFERROR(IF(IF((INDEX(Calculations!$D$107:$R$107,1,(Settings!$B$5-1)*3+2))<0,0,IF((INDEX(Calculations!$D$107:$R$107,1,(Settings!$B$5-1)*3+2))<1,1,IF((INDEX(Calculations!$D$107:$R$107,1,(Settings!$B$5-1)*3+2))<1.5,1.5,IF((INDEX(Calculations!$D$107:$R$107,1,(Settings!$B$5-1)*3+2))<2,2,IF((INDEX(Calculations!$D$107:$R$107,1,(Settings!$B$5-1)*3+2))<4,4,"")))))="","",(IF((INDEX(Calculations!$D$107:$R$107,1,(Settings!$B$5-1)*3+2))<0,0,IF((INDEX(Calculations!$D$107:$R$107,1,(Settings!$B$5-1)*3+2))<1,1,IF((INDEX(Calculations!$D$107:$R$107,1,(Settings!$B$5-1)*3+2))<1.5,1.5,IF((INDEX(Calculations!$D$107:$R$107,1,(Settings!$B$5-1)*3+2))<2,2,IF((INDEX(Calculations!$D$107:$R$107,1,(Settings!$B$5-1)*3+2))<4,4,"")))))*(INDEX(Calculations!$D$91:$R$91,1,(Settings!$B$5-1)*3+2))-(INDEX(Calculations!$D$102:$R$102,1,(Settings!$B$5-1)*3+2)))/(Assumptions!$O$85*(INDEX(Calculations!$D$15:$R$15,1,(Settings!$B$5-1)*3+2)))),"") | C8: =IFERROR(IF(IF((INDEX(Calculations!$D$112:$R$112,1,(Settings!$B$5-1)*3+2))<0,0,IF((INDEX(Calculations!$D$112:$R$112,1,(Settings!$B$5-1)*3+2))<1,1,IF((INDEX(Calculations!$D$112:$R$112,1,(Settings!$B$5-1)*3+2))<1.5,1.5,IF((INDEX(Calculations!$D$112:$R$112,1,(Settings!$B$5-1)*3+2))<2,2,IF((INDEX(Calculations!$D$112:$R$112,1,(Settings!$B$5-1)*3+2))<4,4,"")))))="","",(IF((INDEX(Calculations!$D$112:$R$112,1,(Settings!$B$5-1)*3+2))<0,0,IF((INDEX(Calculations!$D$112:$R$112,1,(Settings!$B$5-1)*3+2))<1,1,IF((INDEX(Calculations!$D$112:$R$112,1,(Settings!$B$5-1)*3+2))<1.5,1.5,IF((INDEX(Calculations!$D$112:$R$112,1,(Settings!$B$5-1)*3+2))<2,2,IF((INDEX(Calculations!$D$112:$R$112,1,(Settings!$B$5-1)*3+2))<4,4,"")))))*(INDEX(Calculations!$D$91:$R$91,1,(Settings!$B$5-1)*3+2))-(INDEX(Calculations!$D$103:$R$103,1,(Settings!$B$5-1)*3+2)))/(Assumptions!$O$85*(INDEX(Calculations!$D$15:$R$15,1,(Settings!$B$5-1)*3+2)))),"") | D8: Loneliness value, causality unclear (row S6); sensitivity only
A9: Value of accredited qualifications (not in the ratios) | B9: =IFERROR((INDEX(Calculations!$D$127:$R$127,1,(Settings!$B$5-1)*3+2)),"") | C9: =IFERROR((INDEX(Calculations!$D$127:$R$127,1,(Settings!$B$5-1)*3+2)),"") | D9: Earnings values that overlap GVA (rows S10, S11)
A10: Benefit-cost ratio with streams outside the range rule put back (MHCLG 5.92 switching test) | B10: =IFERROR((INDEX(Calculations!$D$109:$R$109,1,(Settings!$B$5-1)*3+2)),"") | C10: =IFERROR((INDEX(Calculations!$D$114:$R$114,1,(Settings!$B$5-1)*3+2)),"") | D10: If this changes the category, the excluded stream matters to the value for money judgement
A11: Benefit-cost ratio without the offsetting transfers | B11: =IFERROR((INDEX(Calculations!$D$108:$R$108,1,(Settings!$B$5-1)*3+2)),"") | C11: =IFERROR((INDEX(Calculations!$D$113:$R$113,1,(Settings!$B$5-1)*3+2)),"") | D11: Shows how much of the ratio is rates relief and rent
A12: Benefit-cost ratio without optimism bias on fit-out and operator costs | B12: =IFERROR((INDEX(Calculations!$D$102:$R$102,1,(Settings!$B$5-1)*3+2))/((INDEX(Calculations!$D$91:$R$91,1,(Settings!$B$5-1)*3+2))-(INDEX(Calculations!$D$83:$R$83,1,(Settings!$B$5-1)*3+2))+(INDEX(Calculations!$D$83:$R$83,1,(Settings!$B$5-1)*3+2))/(1+(INDEX(Calculations!$D$82:$R$82,1,(Settings!$B$5-1)*3+2)))-(INDEX(Calculations!$D$84:$R$84,1,(Settings!$B$5-1)*3+2))+(INDEX(Calculations!$D$84:$R$84,1,(Settings!$B$5-1)*3+2))/(1+Assumptions!$O$19/100)),"") | C12: =IFERROR((INDEX(Calculations!$D$103:$R$103,1,(Settings!$B$5-1)*3+2))/((INDEX(Calculations!$D$91:$R$91,1,(Settings!$B$5-1)*3+2))-(INDEX(Calculations!$D$83:$R$83,1,(Settings!$B$5-1)*3+2))+(INDEX(Calculations!$D$83:$R$83,1,(Settings!$B$5-1)*3+2))/(1+(INDEX(Calculations!$D$82:$R$82,1,(Settings!$B$5-1)*3+2)))-(INDEX(Calculations!$D$84:$R$84,1,(Settings!$B$5-1)*3+2))+(INDEX(Calculations!$D$84:$R$84,1,(Settings!$B$5-1)*3+2))/(1+Assumptions!$O$19/100)),"") | D12: Shows how much the optimism bias uplifts matter
A14: To test the announced 3.0% discount rate, change it on the Settings sheet. The ratios recalculate throughout.

Sheet Compare
A1: Compare Proposals
A2: All five proposals on central assumptions, with the low to high range.
A4: Measure | B4: Proposal 1 | C4: Proposal 2 | D4: Proposal 3 | E4: Proposal 4 | F4: Proposal 5
A5: Name | B5: =IF(Inputs!C6="","",Inputs!C6) | C5: =IF(Inputs!D6="","",Inputs!D6) | D5: =IF(Inputs!E6="","",Inputs!E6) | E5: =IF(Inputs!F6="","",Inputs!F6) | F5: =IF(Inputs!G6="","",Inputs!G6)
A6: Use | B6: =IF(Inputs!C9="","",Inputs!C9) | C6: =IF(Inputs!D9="","",Inputs!D9) | D6: =IF(Inputs!E9="","",Inputs!E9) | E6: =IF(Inputs!F9="","",Inputs!F9) | F6: =IF(Inputs!G9="","",Inputs!G9)
A7: Centre | B7: =IF(Inputs!C7="","",Inputs!C7) | C7: =IF(Inputs!D7="","",Inputs!D7) | D7: =IF(Inputs!E7="","",Inputs!E7) | E7: =IF(Inputs!F7="","",Inputs!F7) | F7: =IF(Inputs!G7="","",Inputs!G7)
A8: Category, Gateshead | B8: =Calculations!E111 | C8: =Calculations!H111 | D8: =Calculations!K111 | E8: =Calculations!N111 | F8: =Calculations!Q111
A9: Benefit-cost ratio, Gateshead (central) | B9: =Calculations!E107 | C9: =Calculations!H107 | D9: =Calculations!K107 | E9: =Calculations!N107 | F9: =Calculations!Q107
A10: Range, Gateshead | B10: =IF(Calculations!D107="","",TEXT(Calculations!D107,"0.00")&" to "&TEXT(Calculations!F107,"0.00")) | C10: =IF(Calculations!G107="","",TEXT(Calculations!G107,"0.00")&" to "&TEXT(Calculations!I107,"0.00")) | D10: =IF(Calculations!J107="","",TEXT(Calculations!J107,"0.00")&" to "&TEXT(Calculations!L107,"0.00")) | E10: =IF(Calculations!M107="","",TEXT(Calculations!M107,"0.00")&" to "&TEXT(Calculations!O107,"0.00")) | F10: =IF(Calculations!P107="","",TEXT(Calculations!P107,"0.00")&" to "&TEXT(Calculations!R107,"0.00"))
A11: Category, UK | B11: =Calculations!E116 | C11: =Calculations!H116 | D11: =Calculations!K116 | E11: =Calculations!N116 | F11: =Calculations!Q116
A12: Benefit-cost ratio, UK (central) | B12: =Calculations!E112 | C12: =Calculations!H112 | D12: =Calculations!K112 | E12: =Calculations!N112 | F12: =Calculations!Q112
A13: Robustness | B13: =Calculations!E118 | C13: =Calculations!H118 | D13: =Calculations!K118 | E13: =Calculations!N118 | F13: =Calculations!Q118
A14: Net public cost | B14: =Calculations!E91 | C14: =Calculations!H91 | D14: =Calculations!K91 | E14: =Calculations!N91 | F14: =Calculations!Q91
A15: Council cost | B15: =Calculations!E93 | C15: =Calculations!H93 | D15: =Calculations!K93 | E15: =Calculations!N93 | F15: =Calculations!Q93
A16: Net FTE, Gateshead | B16: =Calculations!E38 | C16: =Calculations!H38 | D16: =Calculations!K38 | E16: =Calculations!N38 | F16: =Calculations!Q38
A17: GVA supported in Gateshead | B17: =Calculations!E44 | C17: =Calculations!H44 | D17: =Calculations!K44 | E17: =Calculations!N44 | F17: =Calculations!Q44
A18: GVA from visitor spend | B18: =Calculations!E124 | C18: =Calculations!H124 | D18: =Calculations!K124 | E18: =Calculations!N124 | F18: =Calculations!Q124

Sheet Settings
A1: Settings
A2: Changeable settings. Defaults follow current Treasury and MHCLG guidance.
A4: Setting | B4: Value | C4: Note
A5: Proposal shown on Results and Sensitivity (1 to 5) | B5: 1 | C5: Pick the proposal column
A6: Discount rate (real) | B6: =Assumptions!$O$5/100 | C6: Green Book 3.5%. The Chancellor has announced 3.0% at the 28 October 2026 Budget; type 3.0% here to test it until the guidance is revised
A7: Discount rate for wellbeing values | B7: =Assumptions!$O$6/100 | C7: Green Book health rate 1.5%
A8: Count employment wellbeing in the UK lens? | B8: No | C8: No by default. Green Book 8.41 assumes full displacement of jobs nationally, and Yes needs evidence signed off by a chief economist (8.42 to 8.43)
A9: Include the legacy of a permanent let in the ratios? | B9: No | C9: Off by default (decision 5). Uses the officer's chance of a permanent let that would not otherwise happen, at market rent for 10 years (row L2)

Sheet Static Data
A1: Static Data
A2: Reference figures keyed in once and reused until the next edition. Each has its edition date, and the status turns red after 12 months.
A4: Item | B4: Value | C4: Price year or unit | D4: Edition or date | E4: Source | F4: Status
A5: STEAM Gateshead day-visitor spend per visit (optional; overrides row X1) | C5: 2025 | E5: STEAM (keyed in by the economic intelligence team) | F5: =IF(B5="","Not entered",IF(ISNUMBER(D5),IF(TODAY()-D5>365,"Due for update","Current"),"Enter the edition date"))
A6: Small business multiplier (RV under £51,000) | B6: 0.432 | C6: 2026-27 | D6: 46318 | E6: GOV.UK, Estimate your business rates | F6: =IF(B6="","Not entered",IF(ISNUMBER(D6),IF(TODAY()-D6>365,"Due for update","Current"),"Enter the edition date"))
A7: Small business multiplier, retail, hospitality and leisure | B7: 0.382 | C7: 2026-27 | D7: 46318 | E7: GOV.UK, Estimate your business rates | F7: =IF(B7="","Not entered",IF(ISNUMBER(D7),IF(TODAY()-D7>365,"Due for update","Current"),"Enter the edition date"))
A8: Standard multiplier (RV £51,000 to £499,999) | B8: 0.48 | C8: 2026-27 | D8: 46318 | E8: GOV.UK, Estimate your business rates | F8: =IF(B8="","Not entered",IF(ISNUMBER(D8),IF(TODAY()-D8>365,"Due for update","Current"),"Enter the edition date"))
A9: Standard multiplier, retail, hospitality and leisure | B9: 0.43 | C9: 2026-27 | D9: 46318 | E9: GOV.UK, Estimate your business rates | F9: =IF(B9="","Not entered",IF(ISNUMBER(D9),IF(TODAY()-D9>365,"Due for update","Current"),"Enter the edition date"))
A10: Multiplier for RV £500,000 and over | B10: 0.508 | C10: 2026-27 | D10: 46318 | E10: GOV.UK, Estimate your business rates | F10: =IF(B10="","Not entered",IF(ISNUMBER(D10),IF(TODAY()-D10>365,"Due for update","Current"),"Enter the edition date"))
A11: Empty properties below this RV are exempt until reoccupied | B11: 2900 | C11: £ RV | D11: 46318 | E11: GOV.UK, Empty property relief | F11: =IF(B11="","Not entered",IF(ISNUMBER(D11),IF(TODAY()-D11>365,"Due for update","Current"),"Enter the edition date"))
A12: Small business rate relief: 100% up to this RV | B12: 12000 | C12: £ RV | D12: 46318 | E12: GOV.UK, Small business rate relief | F12: =IF(B12="","Not entered",IF(ISNUMBER(D12),IF(TODAY()-D12>365,"Due for update","Current"),"Enter the edition date"))
A13: Small business rate relief: tapers to 0% at this RV | B13: 15000 | C13: £ RV | D13: 46318 | E13: GOV.UK, Small business rate relief | F13: =IF(B13="","Not entered",IF(ISNUMBER(D13),IF(TODAY()-D13>365,"Due for update","Current"),"Enter the edition date"))
A14: Mandatory charitable rate relief | B14: 0.8 | C14: share | D14: 46318 | E14: GOV.UK, Charitable rate relief | F14: =IF(B14="","Not entered",IF(ISNUMBER(D14),IF(TODAY()-D14>365,"Due for update","Current"),"Enter the edition date"))
A15: Occupation that restarts the empty exemption | B15: 13 | C15: weeks | D15: 46318 | E15: SI 2024/323, in force 1 April 2024 | F15: =IF(B15="","Not entered",IF(ISNUMBER(D15),IF(TODAY()-D15>365,"Due for update","Current"),"Enter the edition date"))
A16: Empty property exemption | B16: 3 | C16: months | D16: 46318 | E16: GOV.UK, Empty property relief | F16: =IF(B16="","Not entered",IF(ISNUMBER(D16),IF(TODAY()-D16>365,"Due for update","Current"),"Enter the edition date"))
A18: GDP deflator, calendar years (2025 = 100), HM Treasury September 2026 file
A19: Year | B19: Index
A20: 2015 | B20: 72.6589
A21: 2016 | B21: 73.9044
A22: 2017 | B22: 74.99
A23: 2018 | B23: 76.4375
A24: 2019 | B24: 78.3418
A25: 2020 | B25: 82.2004
A26: 2021 | B26: 82.7095
A27: 2022 | B27: 87.4661
A28: 2023 | B28: 92.9927
A29: 2024 | B29: 96.5672
A30: 2025 | B30: 100
A31: 2026 | B31: 102.1831
A33: Council vacancy survey by centre (feeds the chance of a let anyway, row B1)
A34: Centre | B34: Tier | C34: Vacant units at first survey | D34: Of which still vacant at second survey | E34: Months between surveys | F34: Second survey date | G34: Annual re-let rate
A35: Gateshead Primary Shopping Area | B35: Gateshead Primary Shopping Area | G35: =IF(OR(C35="",C35=0,E35=""),"",1-(D35/C35)^(12/E35))
A36: Blaydon | B36: District Centre | G36: =IF(OR(C36="",C36=0,E36=""),"",1-(D36/C36)^(12/E36))
A37: Birtley | B37: District Centre | G37: =IF(OR(C37="",C37=0,E37=""),"",1-(D37/C37)^(12/E37))
A38: Coatsworth Road | B38: District Centre | G38: =IF(OR(C38="",C38=0,E38=""),"",1-(D38/C38)^(12/E38))
A39: Felling | B39: District Centre | G39: =IF(OR(C39="",C39=0,E39=""),"",1-(D39/C39)^(12/E39))
A40: Low Fell | B40: District Centre | G40: =IF(OR(C40="",C40=0,E40=""),"",1-(D40/C40)^(12/E40))
A41: Ryton | B41: District Centre | G41: =IF(OR(C41="",C41=0,E41=""),"",1-(D41/C41)^(12/E41))
A42: Whickham | B42: District Centre | G42: =IF(OR(C42="",C42=0,E42=""),"",1-(D42/C42)^(12/E42))
A43: Wrekenton | B43: District Centre | G43: =IF(OR(C43="",C43=0,E43=""),"",1-(D43/C43)^(12/E43))
...

Sheet Assumptions
A1: Assumptions
A2: From the approved register (research/register). The sheet is protected. Change a value only through the Local override column, with a reason; Results shows any override.
A4: ID | B4: Stream | C4: Parameter | D4: Applies to | E4: Unit | F4: Low | G4: Central | H4: High | I4: Pessimistic end | J4: Grade | K4: Local override | L4: Override reason | M4: Override grade | N4: Value, low scenario | O4: Value, central | P4: Value, high scenario | Q4: Grade used | R4: Source | S4: Edition | T4: Location | U4: Quote | V4: Notes | W4: Link
A5: A1 | B5: Prices and time | C5: Discount rate (social time preference rate) | D5: All costs and non-wellbeing benefits | E5: % a year | G5: 3.5 | J5: Rule | N5: =IF(K5<>"",K5,IF(I5="high",IF(H5="",G5,H5),IF(I5="low",IF(F5="",G5,F5),G5))) | O5: =IF(K5<>"",K5,G5) | P5: =IF(K5<>"",K5,IF(I5="high",IF(F5="",G5,F5),IF(I5="low",IF(H5="",G5,H5),G5))) | Q5: =IF(M5<>"",M5,J5) | R5: HM Treasury, Green Book 2026 | S5: February 2026 | T5: 6.54; discounting guidance 2.1 | U5: 3.5% in real terms for short-term proposals | V5: Watch item. The Chancellor has announced a cut to 3.0% and further Green Book reforms at the 28 October 2026 Budget (GOV.UK news, 'PM puts communities first in government investment rules shake up', 22 October 2026). The published Green Book still says 3.5%, so 3.5% stays until the revised guidance is published; editable in Settings | W5: Open source
A6: A2 | B6: Prices and time | C6: Health discount rate for wellbeing values | D6: All WELLBY-based values | E6: % a year | G6: 1.5 | J6: Rule | N6: =IF(K6<>"",K6,IF(I6="high",IF(H6="",G6,H6),IF(I6="low",IF(F6="",G6,F6),G6))) | O6: =IF(K6<>"",K6,G6) | P6: =IF(K6<>"",K6,IF(I6="high",IF(F6="",G6,F6),IF(I6="low",IF(H6="",G6,H6),G6))) | Q6: =IF(M6<>"",M6,J6) | R6: HM Treasury, Green Book supplementary guidance: discounting | S6: February 2026 | T6: 2.16 to 2.17 | U6: These health and life effects should be discounted at a lower rate of 1.5% | W6: Open source
A7: A3 | B7: Prices and time | C7: Price base | D7: All £ values | E7: year | G7: 2026-27 | J7: Rule | N7: =IF(K7<>"",K7,IF(I7="high",IF(H7="",G7,H7),IF(I7="low",IF(F7="",G7,F7),G7))) | O7: =IF(K7<>"",K7,G7) | P7: =IF(K7<>"",K7,IF(I7="high",IF(F7="",G7,F7),IF(I7="low",IF(H7="",G7,H7),G7))) | Q7: =IF(M7<>"",M7,J7) | R7: HM Treasury GDP deflators, September 2026 (Quarterly National Accounts) | S7: 1 October 2026 | T7: Financial-year and calendar-year columns | U7: Outturn data are as at the Quarterly National Accounts from ONS - last updated 30 September 2026. Forecast data are consistent with OBR EFO data as at the Spring Statement 3 March 2026. | V7: 2026-27 index 102.006 (2025-26 = 100), calendar 2026 index 102.183 (2025 = 100), both from OBR forecast growth. A new file is likely after the 28 October 2026 Budget | W7: Open source
A8: A4 | B8: Prices and time | C8: Uprating factor, 2019 calendar prices to 2026 | D8: Values quoted in 2019 prices | E8: multiplier | G8: 1.3043 | J8: Rule | N8: =IF(K8<>"",K8,IF(I8="high",IF(H8="",G8,H8),IF(I8="low",IF(F8="",G8,F8),G8))) | O8: =IF(K8<>"",K8,G8) | P8: =IF(K8<>"",K8,IF(I8="high",IF(F8="",G8,F8),IF(I8="low",IF(H8="",G8,H8),G8))) | Q8: =IF(M8<>"",M8,J8) | R8: HM Treasury GDP deflators, September 2026 | S8: 1 October 2026 | T8: Calendar-year column (ONS series MNF2) | U8: 2019 = 78.3418; 2026 = 102.183 (2025 = 100) | V8: Our calculation | W8: Open source
A9: A5 | B9: Prices and time | C9: WELLBY uprating factor, 2019 to 2026 prices and 2025 values | D9: All WELLBY-based values in 2019 prices | E9: multiplier | G9: 1.3221 | J9: Rule | N9: =IF(K9<>"",K9,IF(I9="high",IF(H9="",G9,H9),IF(I9="low",IF(F9="",G9,F9),G9))) | O9: =IF(K9<>"",K9,G9) | P9: =IF(K9<>"",K9,IF(I9="high",IF(F9="",G9,F9),IF(I9="low",IF(H9="",G9,H9),G9))) | Q9: =IF(M9<>"",M9,J9) | R9: HM Treasury, Wellbeing Guidance for Appraisal (2021), Annex 2; ONS IHXW | S9: Guidance July 2021; IHXW released 30 September 2026 | T9: Annex 2 uprating formula | U9: the WELLBY value should always be uprated to the appraisal base year using the formula above | V9: Deflator ratio 1.3043 x (real GDP per head 2025 42,313 / 2019 41,875) ^ 1.3. Real growth to 2025, the latest outturn year; our calculation | W9: Open source
A10: A6 | B10: Prices and time | C10: Value of one WELLBY | D10: Wellbeing values | E10: £ per WELLBY | F10: 13220.874 | G10: 17187.137 | H10: 21153.399 | I10: low | J10: Rule | N10: =IF(K10<>"",K10,IF(I10="high",IF(H10="",G10,H10),IF(I10="low",IF(F10="",G10,F10),G10))) | O10: =IF(K10<>"",K10,G10) | P10: =IF(K10<>"",K10,IF(I10="high",IF(F10="",G10,F10),IF(I10="low",IF(H10="",G10,H10),G10))) | Q10: =IF(M10<>"",M10,J10) | R10: HM Treasury, Wellbeing Guidance for Appraisal (2021) | S10: July 2021 (page updated 18 November 2022) | T10: Box 7 and Annex 2 | U10: multiplying by £13,000 [Low: £10,000, High £16,000]. This is the recommended standard value of one wellbeing adjusted life year | V10: 2019 values £10,000 / £13,000 / £16,000 uprated by A5 | W10: Open source
A11: A7 | B11: Prices and time | C11: Appraisal period | D11: All proposals | E11: years | G11: Occupation period | J11: Rule | N11: =IF(K11<>"",K11,IF(I11="high",IF(H11="",G11,H11),IF(I11="low",IF(F11="",G11,F11),G11))) | O11: =IF(K11<>"",K11,G11) | P11: =IF(K11<>"",K11,IF(I11="high",IF(F11="",G11,F11),IF(I11="low",IF(H11="",G11,H11),G11))) | Q11: =IF(M11<>"",M11,J11) | R11: HM Treasury, Green Book 2026 | S11: February 2026 | T11: 6.11 and 6.13 | U11: short defined-period proposals should consider the end of the contract (paraphrase of 6.13) | V11: Decision 11. Anything after the occupation period goes through the legacy switch (rows L1 to L3) | W11: Open source
A12: C1 | B12: Confidence and optimism bias | C12: Confidence grade 1: benefit reduction and cost uplift | D12: Benefit streams, and revenue cost lines other than C7 and C8 | E12: % | G12: benefits -0%, costs +0% | J12: Rule | N12: =IF(K12<>"",K12,IF(I12="high",IF(H12="",G12,H12),IF(I12="low",IF(F12="",G12,F12),G12))) | O12: =IF(K12<>"",K12,G12) | P12: =IF(K12<>"",K12,IF(I12="high",IF(F12="",G12,F12),IF(I12="low",IF(H12="",G12,H12),G12))) | Q12: =IF(M12<>"",M12,J12) | R12: HM Treasury, Supporting public service transformation: CBA guidance for local partnerships | S12: April 2014 | T12: Tables 7.A and 7.B; 7.18 to 7.19 | U12: The confidence grade which the CBA model applies to the data is determined by the lowest assessment in any of the descriptive columns. | V12: Displayed as High (1 to 2), Medium (3 to 4), Low (5 to 6). Decision 4. Applied literally in this register, so data over 5 years old is grade 6 | W12: Open source
A13: C2 | B13: Confidence and optimism bias | C13: Confidence grade 2: benefit reduction and cost uplift | D13: Benefit streams, and revenue cost lines other than C7 and C8 | E13: % | G13: benefits -5%, costs +5% | J13: Rule | N13: =IF(K13<>"",K13,IF(I13="high",IF(H13="",G13,H13),IF(I13="low",IF(F13="",G13,F13),G13))) | O13: =IF(K13<>"",K13,G13) | P13: =IF(K13<>"",K13,IF(I13="high",IF(F13="",G13,F13),IF(I13="low",IF(H13="",G13,H13),G13))) | Q13: =IF(M13<>"",M13,J13) | R13: HM Treasury, Supporting public service transformation: CBA guidance for local partnerships | S13: April 2014 | T13: Tables 7.A and 7.B; 7.18 to 7.19 | U13: The confidence grade which the CBA model applies to the data is determined by the lowest assessment in any of the descriptive columns. | V13: Displayed as High (1 to 2), Medium (3 to 4), Low (5 to 6). Decision 4. Applied literally in this register, so data over 5 years old is grade 6 | W13: Open source
A14: C3 | B14: Confidence and optimism bias | C14: Confidence grade 3: benefit reduction and cost uplift | D14: Benefit streams, and revenue cost lines other than C7 and C8 | E14: % | G14: benefits -10%, costs +10% | J14: Rule | N14: =IF(K14<>"",K14,IF(I14="high",IF(H14="",G14,H14),IF(I14="low",IF(F14="",G14,F14),G14))) | O14: =IF(K14<>"",K14,G14) | P14: =IF(K14<>"",K14,IF(I14="high",IF(F14="",G14,F14),IF(I14="low",IF(H14="",G14,H14),G14))) | Q14: =IF(M14<>"",M14,J14) | R14: HM Treasury, Supporting public service transformation: CBA guidance for local partnerships | S14: April 2014 | T14: Tables 7.A and 7.B; 7.18 to 7.19 | U14: The confidence grade which the CBA model applies to the data is determined by the lowest assessment in any of the descriptive columns. | V14: Displayed as High (1 to 2), Medium (3 to 4), Low (5 to 6). Decision 4. Applied literally in this register, so data over 5 years old is grade 6 | W14: Open source
A15: C4 | B15: Confidence and optimism bias | C15: Confidence grade 4: benefit reduction and cost uplift | D15: Benefit streams, and revenue cost lines other than C7 and C8 | E15: % | G15: benefits -15%, costs +15% | J15: Rule | N15: =IF(K15<>"",K15,IF(I15="high",IF(H15="",G15,H15),IF(I15="low",IF(F15="",G15,F15),G15))) | O15: =IF(K15<>"",K15,G15) | P15: =IF(K15<>"",K15,IF(I15="high",IF(F15="",G15,F15),IF(I15="low",IF(H15="",G15,H15),G15))) | Q15: =IF(M15<>"",M15,J15) | R15: HM Treasury, Supporting public service transformation: CBA guidance for local partnerships | S15: April 2014 | T15: Tables 7.A and 7.B; 7.18 to 7.19 | U15: The confidence grade which the CBA model applies to the data is determined by the lowest assessment in any of the descriptive columns. | V15: Displayed as High (1 to 2), Medium (3 to 4), Low (5 to 6). Decision 4. Applied literally in this register, so data over 5 years old is grade 6 | W15: Open source
A16: C5 | B16: Confidence and optimism bias | C16: Confidence grade 5: benefit reduction and cost uplift | D16: Benefit streams, and revenue cost lines other than C7 and C8 | E16: % | G16: benefits -25%, costs +25% | J16: Rule | N16: =IF(K16<>"",K16,IF(I16="high",IF(H16="",G16,H16),IF(I16="low",IF(F16="",G16,F16),G16))) | O16: =IF(K16<>"",K16,G16) | P16: =IF(K16<>"",K16,IF(I16="high",IF(F16="",G16,F16),IF(I16="low",IF(H16="",G16,H16),G16))) | Q16: =IF(M16<>"",M16,J16) | R16: HM Treasury, Supporting public service transformation: CBA guidance for local partnerships | S16: April 2014 | T16: Tables 7.A and 7.B; 7.18 to 7.19 | U16: The confidence grade which the CBA model applies to the data is determined by the lowest assessment in any of the descriptive columns. | V16: Displayed as High (1 to 2), Medium (3 to 4), Low (5 to 6). Decision 4. Applied literally in this register, so data over 5 years old is grade 6 | W16: Open source
A17: C6 | B17: Confidence and optimism bias | C17: Confidence grade 6: benefit reduction and cost uplift | D17: Benefit streams, and revenue cost lines other than C7 and C8 | E17: % | G17: benefits -40%, costs +40% | J17: Rule | N17: =IF(K17<>"",K17,IF(I17="high",IF(H17="",G17,H17),IF(I17="low",IF(F17="",G17,F17),G17))) | O17: =IF(K17<>"",K17,G17) | P17: =IF(K17<>"",K17,IF(I17="high",IF(F17="",G17,F17),IF(I17="low",IF(H17="",G17,H17),G17))) | Q17: =IF(M17<>"",M17,J17) | R17: HM Treasury, Supporting public service transformation: CBA guidance for local partnerships | S17: April 2014 | T17: Tables 7.A and 7.B; 7.18 to 7.19 | U17: The confidence grade which the CBA model applies to the data is determined by the lowest assessment in any of the descriptive columns. | V17: Displayed as High (1 to 2), Medium (3 to 4), Low (5 to 6). Decision 4. Applied literally in this register, so data over 5 years old is grade 6 | W17: Open source
A18: C7 | B18: Confidence and optimism bias | C18: Capital fit-out optimism bias | D18: Fit-out and works costs | E18: % uplift | F18: 4 | G18: 51 | H18: 51 | I18: high | J18: Rule | N18: =IF(K18<>"",K18,IF(I18="high",IF(H18="",G18,H18),IF(I18="low",IF(F18="",G18,F18),G18))) | O18: =IF(K18<>"",K18,G18) | P18: =IF(K18<>"",K18,IF(I18="high",IF(F18="",G18,F18),IF(I18="low",IF(H18="",G18,H18),G18))) | Q18: =IF(M18<>"",M18,J18) | R18: HM Treasury, Supplementary Green Book guidance: optimism bias; MHCLG Appraisal Guide Annex F | S18: 2013 page date; MHCLG February 2026 | T18: Step Two heading before 3.11; Table 1 (non-standard buildings); MHCLG Annex F F7 | U18: Always start with the upper bound | V18: Non-standard buildings include refurbishment projects (paraphrase of the guidance's definitions). Starts at 51% at proposal stage and steps towards 4% as the Treasury mitigation questions are answered (stage selector). Decision 10 | W18: Open source
A19: C8 | B19: Confidence and optimism bias | C19: Contracted operator cost optimism bias | D19: Operator or management contract costs | E19: % uplift | F19: 0 | G19: 41 | H19: 41 | I19: high | J19: Rule | N19: =IF(K19<>"",K19,IF(I19="high",IF(H19="",G19,H19),IF(I19="low",IF(F19="",G19,F19),G19))) | O19: =IF(K19<>"",K19,G19) | P19: =IF(K19<>"",K19,IF(I19="high",IF(F19="",G19,F19),IF(I19="low",IF(H19="",G19,H19),G19))) | Q19: =IF(M19<>"",M19,J19) | R19: HM Treasury, Supplementary Green Book guidance: optimism bias | S19: 2013 page date | T19: Table 1 (outsourcing); 4.1 | U19: Mott MacDonald was unable to recommend sound upper and lower bound optimism bias levels for operating expenditure (except for outsourcing projects) | V19: Applying the outsourcing bound to a meanwhile operator contract is our judgement, labelled as such | W19: Open source
A20: C9 | B20: Confidence and optimism bias | C20: Value for money categories | D20: Results | E20: benefit-cost ratio bands | G20: Very High >=4; High 2-4; Medium 1.5-2; Acceptable 1-1.5; Poor 0-1; Very Poor <0 | J20: Rule | N20: =IF(K20<>"",K20,IF(I20="high",IF(H20="",G20,H20),IF(I20="low",IF(F20="",G20,F20),G20))) | O20: =IF(K20<>"",K20,G20) | P20: =IF(K20<>"",K20,IF(I20="high",IF(F20="",G20,F20),IF(I20="low",IF(H20="",G20,H20),G20))) | Q20: =IF(M20<>"",M20,J20) | R20: MHCLG Appraisal Guide, 4th edition | S20: February 2026 | T20: 3.55 | U20: The following VfM categories can be defined where public sector costs are positive | W20: Open source
A21: C10 | B21: Confidence and optimism bias | C21: Range rule for uncertain streams | D21: Any monetised stream | E21: ratio | G21: 4 | J21: Rule | N21: =IF(K21<>"",K21,IF(I21="high",IF(H21="",G21,H21),IF(I21="low",IF(F21="",G21,F21),G21))) | O21: =IF(K21<>"",K21,G21) | P21: =IF(K21<>"",K21,IF(I21="high",IF(F21="",G21,F21),IF(I21="low",IF(H21="",G21,H21),G21))) | Q21: =IF(M21<>"",M21,J21) | R21: MHCLG Appraisal Guide, 4th edition | S21: February 2026 | T21: 5.92 | U21: where the uncertain range exceeds four times the midpoint, the monetised figure is not reported and switching values are used instead (paraphrase) | V21: Watch item. The rule sits in the guide's health valuation context; applying it to every stream is our extension | W21: Open source
A22: B1 | B22: Business as Usual | C22: Chance the unit is let commercially anyway during the occupation period | D22: BAU column, all proposals | E22: % | F22: 10 | G22: 20 | H22: 40 | I22: high | J22: 6 | N22: =IF(K22<>"",K22,IF(I22="high",IF(H22="",G22,H22),IF(I22="low",IF(F22="",G22,F22),G22))) | O22: =IF(K22<>"",K22,G22) | P22: =IF(K22<>"",K22,IF(I22="high",IF(F22="",G22,F22),IF(I22="low",IF(H22="",G22,H22),G22))) | Q22: =IF(M22<>"",M22,J22) | R22: Open Doors Pilot Programme evaluation (IFF Research for MHCLG); HSRA explanatory memorandum | S22: November 2020; 2024 | T22: Executive summary (counterfactual exercise); EM 5.2 | U22: Three of the five landlords who were not part of the Open Doors scheme ... said their properties were vacant at the time of interview (Open Doors). Over eight in ten of these vacant properties have been empty for more than two years (Whythawk 2021, quoted in EM 5.2). | V22: High = Open Doors counterfactual (2 of 5 not reported vacant; tiny sample). Low and central are our judgement for units vacant over a year. Override with the council's own vacancy register where held | W22: Open source
A23: B2 | B23: Business as Usual | C23: Empty property rates exemption | D23: BAU rates position | E23: months | G23: 3 | J23: Rule | N23: =IF(K23<>"",K23,IF(I23="high",IF(H23="",G23,H23),IF(I23="low",IF(F23="",G23,F23),G23))) | O23: =IF(K23<>"",K23,G23) | P23: =IF(K23<>"",K23,IF(I23="high",IF(F23="",G23,F23),IF(I23="low",IF(H23="",G23,H23),G23))) | Q23: =IF(M23<>"",M23,J23) | R23: GOV.UK, Empty property relief | S23: Checked 23 October 2026 | T23: Standard relief | U23: you do not have to pay business rates on your empty property for 3 months | V23: After 3 months most owners pay full rates. Listed buildings and RV under £2,900 exempt until reoccupied | W23: Open source
A24: B3 | B24: Business as Usual | C24: Occupation needed to restart the empty rates exemption | D24: Transfer line (landlord rates) | E24: weeks | G24: 13 | J24: Rule | N24: =IF(K24<>"",K24,IF(I24="high",IF(H24="",G24,H24),IF(I24="low",IF(F24="",G24,F24),G24))) | O24: =IF(K24<>"",K24,G24) | P24: =IF(K24<>"",K24,IF(I24="high",IF(F24="",G24,F24),IF(I24="low",IF(H24="",G24,H24),G24))) | Q24: =IF(M24<>"",M24,J24) | R24: Non-Domestic Rating (Unoccupied Property) (England) (Amendment) Regulations 2024, SI 2024/323 | S24: In force 1 April 2024 | T24: Regulation 2 | U24: in regulation 5 (continuous occupation), for "six weeks" substitute "13 weeks" | V24: A meanwhile occupation of 13 weeks or more restarts the landlord's 3-month exemption afterwards: a transfer from the council to the landlord | W24: Open source
A25: B4 | B25: Business as Usual | C25: Business rates multipliers 2026-27 | D25: Rates lines | E25: pence per £ RV | G25: Small RHL 38.2; small other 43.2; standard RHL 43.0; standard other 48.0; RV £500,000+ 50.8 | J25: Rule | N25: =IF(K25<>"",K25,IF(I25="high",IF(H25="",G25,H25),IF(I25="low",IF(F25="",G25,F25),G25))) | O25: =IF(K25<>"",K25,G25) | P25: =IF(K25<>"",K25,IF(I25="high",IF(F25="",G25,F25),IF(I25="low",IF(H25="",G25,H25),G25))) | Q25: =IF(M25<>"",M25,J25) | R25: GOV.UK, Estimate your business rates | S25: Checked 23 October 2026 | T25: England, 2026 to 2027 | U25: 43.2 pence if your rateable value is below £51,000 ... 38.2 pence if your rateable value is below £51,000 | V25: RHL rates apply to eligible occupied properties only; small multipliers apply where RV is below £51,000 | W25: Open source
A26: B5 | B26: Business as Usual | C26: Small business rate relief | D26: Occupier rates, transfer line | E26: RV thresholds | G26: 100% to £12,000; tapers to 0% at £15,000 | J26: Rule | N26: =IF(K26<>"",K26,IF(I26="high",IF(H26="",G26,H26),IF(I26="low",IF(F26="",G26,F26),G26))) | O26: =IF(K26<>"",K26,G26) | P26: =IF(K26<>"",K26,IF(I26="high",IF(F26="",G26,F26),IF(I26="low",IF(H26="",G26,H26),G26))) | Q26: =IF(M26<>"",M26,J26) | R26: GOV.UK, Small business rate relief | S26: Checked 23 October 2026 | T26: Thresholds | U26: You will not pay business rates on a property with a rateable value of £12,000 or less | W26: Open source
A27: B6 | B27: Business as Usual | C27: Charitable rate relief | D27: Occupier rates where a charity occupies | E27: % | G27: 80 | H27: 100 | J27: Rule | N27: =IF(K27<>"",K27,IF(I27="high",IF(H27="",G27,H27),IF(I27="low",IF(F27="",G27,F27),G27))) | O27: =IF(K27<>"",K27,G27) | P27: =IF(K27<>"",K27,IF(I27="high",IF(F27="",G27,F27),IF(I27="low",IF(H27="",G27,H27),G27))) | Q27: =IF(M27<>"",M27,J27) | R27: GOV.UK, Charitable rate relief | S27: Checked 23 October 2026 | U27: Charitable rate relief gives you up to 80% off your business rates bill ... Your local council may also be able to top up the discount | V27: High = 100% where the council tops up with discretionary relief (as in Open Doors, where the programme paid the remaining 20%) | W27: Open source
A28: B7 | B28: Business as Usual | C28: Holding cost of a council-owned empty unit | D28: BAU cost, council-owned units only | E28: % of existing value a year | G28: 2 | J28: Rule | N28: =IF(K28<>"",K28,IF(I28="high",IF(H28="",G28,H28),IF(I28="low",IF(F28="",G28,F28),G28))) | O28: =IF(K28<>"",K28,G28) | P28: =IF(K28<>"",K28,IF(I28="high",IF(F28="",G28,F28),IF(I28="low",IF(H28="",G28,H28),G28))) | Q28: =IF(M28<>"",M28,J28) | R28: MHCLG Appraisal Guide technical annex | S28: 18 February 2026 | T28: Annex A10 and D17 | U28: industry standards indicate these can be assumed to be 2% of the existing value of the land per year | V28: Alternative to B9, used only without site-specific evidence: the annex holding cost covers maintenance and security. It applies to the unit's book or market value; with an existing use value of zero (B8) it gives zero, so B9 carries the cost | W28: Open source
A29: B8 | B29: Business as Usual | C29: Existing use value of a long-vacant unit | D29: Value of space | E29: £ | G29: 0 | J29: Rule | N29: =IF(K29<>"",K29,IF(I29="high",IF(H29="",G29,H29),IF(I29="low",IF(F29="",G29,F29),G29))) | O29: =IF(K29<>"",K29,G29) | P29: =IF(K29<>"",K29,IF(I29="high",IF(F29="",G29,F29),IF(I29="low",IF(H29="",G29,H29),G29))) | Q29: =IF(M29<>"",M29,J29) | R29: MHCLG Appraisal Guide technical annex | S29: 18 February 2026 | T29: Annex A7 | U29: where there is no active economic use of the site and there will not be for the foreseeable future without public sector intervention, it may be appropriate to apply an existing use value of zero | W29: Open source
A30: B9 | B30: Business as Usual | C30: Security, inspection and maintenance of an empty unit | D30: BAU cost | E30: £ a year | G30: User input | J30: 6 | N30: =IF(K30<>"",K30,IF(I30="high",IF(H30="",G30,H30),IF(I30="low",IF(F30="",G30,F30),G30))) | O30: =IF(K30<>"",K30,G30) | P30: =IF(K30<>"",K30,IF(I30="high",IF(F30="",G30,F30),IF(I30="low",IF(H30="",G30,H30),G30))) | Q30: =IF(M30<>"",M30,J30) | R30: No published benchmark found | V30: Evidence gap. Officer enters the council's own cost; flagged until entered
A31: V1 | B31: Value of the space | C31: Market rent (high value of the space) | D31: Both ratios | E31: £ a year | G31: Unit rateable value x V3 | J31: 3 | N31: =IF(K31<>"",K31,IF(I31="high",IF(H31="",G31,H31),IF(I31="low",IF(F31="",G31,F31),G31))) | O31: =IF(K31<>"",K31,G31) | P31: =IF(K31<>"",K31,IF(I31="high",IF(F31="",G31,F31),IF(I31="low",IF(H31="",G31,H31),G31))) | Q31: =IF(M31<>"",M31,J31) | R31: GOV.UK, How your rates are calculated; VOA Find a business rates valuation (per property) | S31: 2026 rating list, valuation date 1 April 2024 | U31: This is its open market rental value on 1 April 2024, based on an estimate by the Valuation Office (VO). | V31: Officer looks up the unit's rateable value (free, per property). The bulk VOA list needs a restricted licence and is not used | W31: Open source
A32: V2 | B32: Value of the space | C32: Rent a comparable meanwhile occupier pays (low value of the space) | D32: Both ratios | E32: £ a year | G32: Rent actually agreed | J32: 5 | N32: =IF(K32<>"",K32,IF(I32="high",IF(H32="",G32,H32),IF(I32="low",IF(F32="",G32,F32),G32))) | O32: =IF(K32<>"",K32,G32) | P32: =IF(K32<>"",K32,IF(I32="high",IF(F32="",G32,F32),IF(I32="low",IF(H32="",G32,H32),G32))) | Q32: =IF(M32<>"",M32,J32) | R32: Revealed preference: the occupier's own rent | T32: Green Book 8.6 valuation hierarchy (market prices first) | V32: Zero where the occupier pays no rent. Central = midpoint of V1 and V2 (our judgement). Grade 5 so the 25% benefit cut applies; decision 2. V1 and V2 are both netted for the chance of a let anyway (B1)
A33: V3 | B33: Value of the space | C33: Uprating, 2024-25 rental values to 2026-27 | D33: V1 | E33: multiplier | G33: 1.0542 | J33: Rule | N33: =IF(K33<>"",K33,IF(I33="high",IF(H33="",G33,H33),IF(I33="low",IF(F33="",G33,F33),G33))) | O33: =IF(K33<>"",K33,G33) | P33: =IF(K33<>"",K33,IF(I33="high",IF(F33="",G33,F33),IF(I33="low",IF(H33="",G33,H33),G33))) | Q33: =IF(M33<>"",M33,J33) | R33: HM Treasury GDP deflators, September 2026 | S33: 1 October 2026 | T33: Financial-year column | U33: 2024-25 = 96.757; 2026-27 = 102.006 | V33: Our calculation; a general price deflator, not a rent index | W33: Open source
A34: V4 | B34: Value of the space | C34: Rent paid by the council to a private landlord | D34: Cost and transfer lines | E34: £ a year | G34: Officer input | J34: Rule | N34: =IF(K34<>"",K34,IF(I34="high",IF(H34="",G34,H34),IF(I34="low",IF(F34="",G34,F34),G34))) | O34: =IF(K34<>"",K34,G34) | P34: =IF(K34<>"",K34,IF(I34="high",IF(F34="",G34,F34),IF(I34="low",IF(H34="",G34,H34),G34))) | Q34: =IF(M34<>"",M34,J34) | R34: MHCLG Appraisal Guide, 4th edition | S34: February 2026 | T34: 3.34 and footnote 15 | V34: Decisions 2 and 12. A transfer: counted in net public cost with an equal offsetting benefit to the landlord. The value of the space (V1, V2) is the occupier's use of it, a separate benefit, so nothing is counted twice. Rent the occupier pays is a transfer between private parties and is left out | W34: Open source
A35: J1 | B35: Jobs | C35: Employment density (floor area per FTE) | D35: Pop-up retail | E35: m2 per FTE | F35: 15 | G35: 17.5 | H35: 20 | I35: high | J35: 6 | N35: =IF(K35<>"",K35,IF(I35="high",IF(H35="",G35,H35),IF(I35="low",IF(F35="",G35,F35),G35))) | O35: =IF(K35<>"",K35,G35) | P35: =IF(K35<>"",K35,IF(I35="high",IF(F35="",G35,F35),IF(I35="low",IF(H35="",G35,H35),G35))) | Q35: =IF(M35<>"",M35,J35) | R35: HCA Employment Density Guide, 3rd edition (Bilfinger GVA) | S35: November 2015 | T35: Section 4 density matrix, page 29 | U35: A1 retail, high street (NIA) | V35: Low density = more jobs. Central is the midpoint (our calculation). The Guide says it should not be relied on for appraisals needing central government approval; the method note says so | W35: Open source
